<sdf version='1.6'>
  <model name='ezgripper_stand_alone'>
    <link name='only_ezgripper_palm_link'>
      <pose frame=''>0.049 0 0.2 0 -0 0</pose>
      <inertial>
        <pose frame=''>0 0 0 0 -0 0</pose>
        <mass>0.3</mass>
        <inertia>
          <ixx>0.01</ixx>
          <ixy>0</ixy>
          <ixz>0</ixz>
          <iyy>0.01</iyy>
          <iyz>0</iyz>
          <izz>0.01</izz>
        </inertia>
      </inertial>
      <collision name='only_ezgripper_palm_link_collision'>
        <pose frame=''>0 0 0 0 -0 0</pose>
        <geometry>
          <mesh>
            <scale>1 1 1</scale>
            <uri>model://ezgripper_driver/meshes/collision/SAKE_Palm_Dual.stl</uri>
          </mesh>
        </geometry>
      </collision>
      <visual name='only_ezgripper_palm_link_visual'>
        <pose frame=''>0 0 0 0 -0 0</pose>
        <geometry>
          <mesh>
            <scale>1 1 1</scale>
            <uri>model://ezgripper_driver/meshes/visual/SAKE_Palm_Dual.stl</uri>
          </mesh>
        </geometry>
      </visual>
    </link>
    <joint name='fixed' type='revolute'>
      <child>only_ezgripper_palm_link</child>
      <parent>world</parent>
      <axis>
        <limit>
          <lower>0</lower>
          <upper>0</upper>
        </limit>
        <dynamics>
          <damping>0</damping>
          <friction>0</friction>
          <spring_reference>0</spring_reference>
          <spring_stiffness>0</spring_stiffness>
        </dynamics>
        <use_parent_model_frame>1</use_parent_model_frame>
        <xyz>0 0 1</xyz>
      </axis>
    </joint>
    <link name='only_ezgripper_finger_1'>
      <pose frame=''>0.1546 0.03 0.2 1.5708 -0 3.14159</pose>
      <inertial>
        <pose frame=''>-0.064 0 0.00132 0 -0 0</pose>
        <mass>0.025</mass>
        <inertia>
          <ixx>0.01</ixx>
          <ixy>0</ixy>
          <ixz>0</ixz>
          <iyy>0.01</iyy>
          <iyz>0</iyz>
          <izz>0.01</izz>
        </inertia>
      </inertial>
      <collision name='only_ezgripper_finger_1_collision'>
        <pose frame=''>0 0 0 0 -0 0</pose>
        <geometry>
          <mesh>
            <scale>1 1 1</scale>
            <uri>model://ezgripper_driver/meshes/collision/SAKE_Finger.stl</uri>
          </mesh>
        </geometry>
      </collision>
      <visual name='only_ezgripper_finger_1_visual'>
        <pose frame=''>0 0 0 0 -0 0</pose>
        <geometry>
          <mesh>
            <scale>1 1 1</scale>
            <uri>model://ezgripper_driver/meshes/visual/SAKE_Finger.stl</uri>
          </mesh>
        </geometry>
      </visual>
    </link>
    <joint name='only_ezgripper_knuckle_1' type='revolute'>
      <child>only_ezgripper_finger_1</child>
      <parent>only_ezgripper_palm_link</parent>
      <axis>
        <xyz>0 4e-06 1</xyz>
        <limit>
          <lower>-0.27</lower>
          <upper>1.57075</upper>
          <effort>1</effort>
          <velocity>3.67</velocity>
        </limit>
        <dynamics>
          <spring_reference>0.5</spring_reference>
          <spring_stiffness>10</spring_stiffness>
        </dynamics>
        <use_parent_model_frame>1</use_parent_model_frame>
      </axis>
      <physics>
        <provide_feedback>1</provide_feedback>
        <ode>
          <provide_feedback>1</provide_feedback>
          <implicit_spring_damper>1</implicit_spring_damper>
          <cfm_damping>1</cfm_damping>
          <fudge_factor>0.2</fudge_factor>
          <limit>
            <cfm>0.8</cfm>
            <erp>100</erp>
          </limit>
        </ode>
      </physics>
    </joint>
    <link name='only_ezgripper_finger_2'>
      <pose frame=''>0.1546 -0.03 0.2 -1.5708 -0 3.14159</pose>
      <inertial>
        <pose frame=''>-0.064 0 0.00132 0 -0 0</pose>
        <mass>0.025</mass>
        <inertia>
          <ixx>0.01</ixx>
          <ixy>0</ixy>
          <ixz>0</ixz>
          <iyy>0.01</iyy>
          <iyz>0</iyz>
          <izz>0.01</izz>
        </inertia>
      </inertial>
      <collision name='only_ezgripper_finger_2_collision'>
        <pose frame=''>0 0 0 0 -0 0</pose>
        <geometry>
          <mesh>
            <scale>1 1 1</scale>
            <uri>model://ezgripper_driver/meshes/collision/SAKE_Finger.stl</uri>
          </mesh>
        </geometry>
      </collision>
      <visual name='only_ezgripper_finger_2_visual'>
        <pose frame=''>0 0 0 0 -0 0</pose>
        <geometry>
          <mesh>
            <scale>1 1 1</scale>
            <uri>model://ezgripper_driver/meshes/visual/SAKE_Finger.stl</uri>
          </mesh>
        </geometry>
      </visual>
    </link>
    <joint name='only_ezgripper_knuckle_2' type='revolute'>
      <child>only_ezgripper_finger_2</child>
      <parent>only_ezgripper_palm_link</parent>
      <axis>
        <xyz>0 4e-06 -1</xyz>
        <limit>
          <lower>-0.27</lower>
          <upper>1.57075</upper>
          <effort>1</effort>
          <velocity>3.67</velocity>
        </limit>
        <dynamics>
          <spring_reference>0.5</spring_reference>
          <spring_stiffness>10</spring_stiffness>
        </dynamics>
        <use_parent_model_frame>1</use_parent_model_frame>
      </axis>
      <physics>
        <provide_feedback>1</provide_feedback>
        <ode>
          <provide_feedback>1</provide_feedback>
          <implicit_spring_damper>1</implicit_spring_damper>
          <cfm_damping>1</cfm_damping>
          <fudge_factor>0.2</fudge_factor>
          <limit>
            <cfm>0.8</cfm>
            <erp>100</erp>
          </limit>
        </ode>
      </physics>
    </joint>
    <static>0</static>
    <plugin name='gazebo_ros_control' filename='libgazebo_ros_control.so'/>
  </model>
</sdf>
