<sdf version='1.6'>
  <model name='ezgripper_stand_alone'>
    <link name='ezgripper_xy'>
      <pose frame=''>0 0 0 0 -0 0</pose>
      <inertial>
        <pose frame=''>0 0 0 0 -0 0</pose>
        <mass>1</mass>
        <inertia>
          <ixx>1</ixx>
          <ixy>0</ixy>
          <ixz>0</ixz>
          <iyy>1</iyy>
          <iyz>0</iyz>
          <izz>1</izz>
        </inertia>
      </inertial>
    </link>
    <joint name='base_x' type='prismatic'>
      <child>ezgripper_xy</child>
      <parent>world</parent>
      <axis>
        <xyz>1 0 0</xyz>
        <limit>
          <lower>-10</lower>
          <upper>10</upper>
          <effort>100</effort>
          <velocity>2</velocity>
        </limit>
        <dynamics>
          <spring_reference>0</spring_reference>
          <spring_stiffness>0</spring_stiffness>
        </dynamics>
        <use_parent_model_frame>1</use_parent_model_frame>
      </axis>
    </joint>
    <link name='ezgripper_yz'>
      <pose frame=''>0 0 0 0 -0 0</pose>
      <inertial>
        <pose frame=''>0 0 0 0 -0 0</pose>
        <mass>1</mass>
        <inertia>
          <ixx>1</ixx>
          <ixy>0</ixy>
          <ixz>0</ixz>
          <iyy>1</iyy>
          <iyz>0</iyz>
          <izz>1</izz>
        </inertia>
      </inertial>
    </link>
    <joint name='base_y' type='prismatic'>
      <child>ezgripper_yz</child>
      <parent>ezgripper_xy</parent>
      <axis>
        <xyz>0 1 0</xyz>
        <limit>
          <lower>-10</lower>
          <upper>10</upper>
          <effort>100</effort>
          <velocity>2</velocity>
        </limit>
        <dynamics>
          <spring_reference>0</spring_reference>
          <spring_stiffness>0</spring_stiffness>
        </dynamics>
        <use_parent_model_frame>1</use_parent_model_frame>
      </axis>
    </joint>
    <link name='ezgripper_z_rx'>
      <pose frame=''>0 0 0 0 -0 0</pose>
      <inertial>
        <pose frame=''>0 0 0 0 -0 0</pose>
        <mass>1</mass>
        <inertia>
          <ixx>1</ixx>
          <ixy>0</ixy>
          <ixz>0</ixz>
          <iyy>1</iyy>
          <iyz>0</iyz>
          <izz>1</izz>
        </inertia>
      </inertial>
    </link>
    <joint name='base_z' type='prismatic'>
      <child>ezgripper_z_rx</child>
      <parent>ezgripper_yz</parent>
      <axis>
        <xyz>0 0 1</xyz>
        <limit>
          <lower>-10</lower>
          <upper>10</upper>
          <effort>100</effort>
          <velocity>2</velocity>
        </limit>
        <dynamics>
          <spring_reference>0</spring_reference>
          <spring_stiffness>0</spring_stiffness>
        </dynamics>
        <use_parent_model_frame>1</use_parent_model_frame>
      </axis>
    </joint>
    <link name='ezgripper_rx_ry'>
      <pose frame=''>0 0 0 0 -0 0</pose>
      <inertial>
        <pose frame=''>0 0 0 0 -0 0</pose>
        <mass>1</mass>
        <inertia>
          <ixx>1</ixx>
          <ixy>0</ixy>
          <ixz>0</ixz>
          <iyy>1</iyy>
          <iyz>0</iyz>
          <izz>1</izz>
        </inertia>
      </inertial>
    </link>
    <joint name='base_rx' type='revolute'>
      <child>ezgripper_rx_ry</child>
      <parent>ezgripper_z_rx</parent>
      <axis>
        <xyz>1 0 0</xyz>
        <limit>
          <lower>-3.1415</lower>
          <upper>3.1415</upper>
          <effort>100</effort>
          <velocity>2</velocity>
        </limit>
        <dynamics>
          <spring_reference>0</spring_reference>
          <spring_stiffness>0</spring_stiffness>
        </dynamics>
        <use_parent_model_frame>1</use_parent_model_frame>
      </axis>
    </joint>
    <link name='ezgripper_ry_rz'>
      <pose frame=''>0 0 0 0 -0 0</pose>
      <inertial>
        <pose frame=''>0 0 0 0 -0 0</pose>
        <mass>1</mass>
        <inertia>
          <ixx>1</ixx>
          <ixy>0</ixy>
          <ixz>0</ixz>
          <iyy>1</iyy>
          <iyz>0</iyz>
          <izz>1</izz>
        </inertia>
      </inertial>
    </link>
    <joint name='base_ry' type='revolute'>
      <child>ezgripper_ry_rz</child>
      <parent>ezgripper_rx_ry</parent>
      <axis>
        <xyz>0 1 0</xyz>
        <limit>
          <lower>-3.1415</lower>
          <upper>3.1415</upper>
          <effort>100</effort>
          <velocity>2</velocity>
        </limit>
        <dynamics>
          <spring_reference>0</spring_reference>
          <spring_stiffness>0</spring_stiffness>
        </dynamics>
        <use_parent_model_frame>1</use_parent_model_frame>
      </axis>
    </joint>
    <link name='only_ezgripper_palm_link'>
      <pose frame=''>0 0 0 0 -0 0</pose>
      <inertial>
        <pose frame=''>0 0 0.005484 0 -0 0</pose>
        <mass>0.31</mass>
        <inertia>
          <ixx>0.0202797</ixx>
          <ixy>0</ixy>
          <ixz>-8.67362e-19</ixz>
          <iyy>0.0202797</iyy>
          <iyz>0</iyz>
          <izz>0.02</izz>
        </inertia>
      </inertial>
      <collision name='only_ezgripper_palm_link_collision'>
        <pose frame=''>0 0 0 0 -0 0</pose>
        <geometry>
          <mesh>
            <scale>1 1 1</scale>
            <uri>model://ezgripper_driver/meshes/collision/SAKE_Palm_Dual.stl</uri>
          </mesh>
        </geometry>
      </collision>
      <visual name='only_ezgripper_palm_link_visual'>
        <pose frame=''>0 0 0 0 -0 0</pose>
        <geometry>
          <mesh>
            <scale>1 1 1</scale>
            <uri>model://ezgripper_driver/meshes/visual/SAKE_Palm_Dual.stl</uri>
          </mesh>
        </geometry>
      </visual>
      <visual name='only_ezgripper_palm_link_fixed_joint_lump__only_ezgripper_kinect_link_visual_1'>
        <pose frame=''>0 0 0.17 0 0.5 0</pose>
        <geometry>
          <box>
            <size>0.01 0.02 0.01</size>
          </box>
        </geometry>
        <material>
          <script>
            <name>Gazebo/Red</name>
            <uri>file://media/materials/scripts/gazebo.material</uri>
          </script>
        </material>
      </visual>
      <velocity_decay/>
      <gravity>1</gravity>
      <velocity_decay/>
      <self_collide>0</self_collide>
      <sensor name='rgbd_camera_frame_sensor' type='depth'>
        <always_on>1</always_on>
        <update_rate>6</update_rate>
        <camera name='__default__'>
          <horizontal_fov>1.01229</horizontal_fov>
          <image>
            <width>320</width>
            <height>240</height>
          </image>
          <clip>
            <near>0.05</near>
            <far>4</far>
          </clip>
        </camera>
        <plugin name='rgbd_camera_frame_controller' filename='libgazebo_ros_openni_kinect.so'>
          <alwaysOn>true</alwaysOn>
          <updateRate>6.0</updateRate>
          <cameraName>camera</cameraName>
          <imageTopicName>ir/image_raw</imageTopicName>
          <cameraInfoTopicName>ir/camera_info</cameraInfoTopicName>
          <depthImageTopicName>depth_registered/sw_registered/image_rect_raw</depthImageTopicName>
          <depthImageCameraInfoTopicName>depth/camera_info</depthImageCameraInfoTopicName>
          <pointCloudTopicName>/overhead_kinect1/depth_registered/points</pointCloudTopicName>
          <frameName>kinect_frame</frameName>
          <pointCloudCutoff>0.05</pointCloudCutoff>
          <pointCloudCutoffMax>5</pointCloudCutoffMax>
          <rangeMax>4.0</rangeMax>
        </plugin>
        <pose frame=''>0 0 0.17 0 0.5 0</pose>
      </sensor>
    </link>
    <joint name='base_rz' type='revolute'>
      <child>only_ezgripper_palm_link</child>
      <parent>ezgripper_ry_rz</parent>
      <axis>
        <xyz>0 0 1</xyz>
        <limit>
          <lower>-3.1415</lower>
          <upper>3.1415</upper>
          <effort>100</effort>
          <velocity>2</velocity>
        </limit>
        <dynamics>
          <spring_reference>0</spring_reference>
          <spring_stiffness>0</spring_stiffness>
        </dynamics>
        <use_parent_model_frame>1</use_parent_model_frame>
      </axis>
    </joint>
    <link name='only_ezgripper_finger_1'>
      <pose frame=''>0.1056 0.03 0 1.5708 -0 3.14159</pose>
      <inertial>
        <pose frame=''>-0.03121 0 -0.00256 0 -0 0</pose>
        <mass>0.025</mass>
        <inertia>
          <ixx>0.01</ixx>
          <ixy>0</ixy>
          <ixz>0</ixz>
          <iyy>0.01</iyy>
          <iyz>0</iyz>
          <izz>0.01</izz>
        </inertia>
      </inertial>
      <collision name='only_ezgripper_finger_1_collision'>
        <pose frame=''>0 0 0 0 -0 0</pose>
        <geometry>
          <mesh>
            <scale>1 1 1</scale>
            <uri>model://ezgripper_driver/meshes/collision/SAKE_Finger_Link1.stl</uri>
          </mesh>
        </geometry>
      </collision>
      <visual name='only_ezgripper_finger_1_visual'>
        <pose frame=''>0 0 0 0 -0 0</pose>
        <geometry>
          <mesh>
            <scale>1 1 1</scale>
            <uri>model://ezgripper_driver/meshes/visual/SAKE_Finger_Link1.stl</uri>
          </mesh>
        </geometry>
      </visual>
    </link>
    <joint name='only_ezgripper_knuckle_1' type='revolute'>
      <child>only_ezgripper_finger_1</child>
      <parent>only_ezgripper_palm_link</parent>
      <axis>
        <xyz>0 4e-06 1</xyz>
        <limit>
          <lower>-0.27</lower>
          <upper>1.57075</upper>
          <effort>1</effort>
          <velocity>3.67</velocity>
        </limit>
        <dynamics>
          <damping>0.1</damping>
          <friction>0</friction>
          <spring_reference>1.57075</spring_reference>
          <spring_stiffness>0.1</spring_stiffness>
        </dynamics>
        <use_parent_model_frame>1</use_parent_model_frame>
      </axis>
    </joint>
    <link name='only_ezgripper_finger_tip_1'>
      <pose frame=''>0.1711 0.03 0 1.5708 -1e-06 -2.8816</pose>
      <inertial>
        <pose frame=''>-0.03108 0 -0.00325 0 -0 0</pose>
        <mass>0.025</mass>
        <inertia>
          <ixx>0.01</ixx>
          <ixy>0</ixy>
          <ixz>0</ixz>
          <iyy>0.01</iyy>
          <iyz>0</iyz>
          <izz>0.01</izz>
        </inertia>
      </inertial>
      <collision name='only_ezgripper_finger_tip_1_collision'>
        <pose frame=''>0 0 0 0 -0 0</pose>
        <geometry>
          <mesh>
            <scale>1 1 1</scale>
            <uri>model://ezgripper_driver/meshes/collision/SAKE_Finger_Link2.stl</uri>
          </mesh>
        </geometry>
      </collision>
      <visual name='only_ezgripper_finger_tip_1_visual'>
        <pose frame=''>0 0 0 0 -0 0</pose>
        <geometry>
          <mesh>
            <scale>1 1 1</scale>
            <uri>model://ezgripper_driver/meshes/visual/SAKE_Finger_Link2.stl</uri>
          </mesh>
        </geometry>
      </visual>
    </link>
    <joint name='only_ezgripper_tip_joint_1' type='revolute'>
      <child>only_ezgripper_finger_tip_1</child>
      <parent>only_ezgripper_finger_1</parent>
      <axis>
        <xyz>0 4e-06 1</xyz>
        <limit>
          <lower>-1.57</lower>
          <upper>0.26</upper>
          <effort>1</effort>
          <velocity>3.67</velocity>
        </limit>
        <dynamics>
          <damping>0.1</damping>
          <friction>0</friction>
          <spring_reference>0.31</spring_reference>
          <spring_stiffness>0.2</spring_stiffness>
        </dynamics>
        <use_parent_model_frame>1</use_parent_model_frame>
      </axis>
    </joint>
    <link name='only_ezgripper_finger_2'>
      <pose frame=''>0.1056 -0.03 0 -1.5708 -0 3.14159</pose>
      <inertial>
        <pose frame=''>-0.03121 0 -0.00256 0 -0 0</pose>
        <mass>0.025</mass>
        <inertia>
          <ixx>0.01</ixx>
          <ixy>0</ixy>
          <ixz>0</ixz>
          <iyy>0.01</iyy>
          <iyz>0</iyz>
          <izz>0.01</izz>
        </inertia>
      </inertial>
      <collision name='only_ezgripper_finger_2_collision'>
        <pose frame=''>0 0 0 0 -0 0</pose>
        <geometry>
          <mesh>
            <scale>1 1 1</scale>
            <uri>model://ezgripper_driver/meshes/collision/SAKE_Finger_Link1.stl</uri>
          </mesh>
        </geometry>
      </collision>
      <visual name='only_ezgripper_finger_2_visual'>
        <pose frame=''>0 0 0 0 -0 0</pose>
        <geometry>
          <mesh>
            <scale>1 1 1</scale>
            <uri>model://ezgripper_driver/meshes/visual/SAKE_Finger_Link1.stl</uri>
          </mesh>
        </geometry>
      </visual>
    </link>
    <joint name='only_ezgripper_knuckle_2' type='revolute'>
      <child>only_ezgripper_finger_2</child>
      <parent>only_ezgripper_palm_link</parent>
      <axis>
        <xyz>0 4e-06 -1</xyz>
        <limit>
          <lower>-0.27</lower>
          <upper>1.57075</upper>
          <effort>1</effort>
          <velocity>3.67</velocity>
        </limit>
        <dynamics>
          <damping>0.1</damping>
          <friction>0</friction>
          <spring_reference>1.57075</spring_reference>
          <spring_stiffness>0.1</spring_stiffness>
        </dynamics>
        <use_parent_model_frame>1</use_parent_model_frame>
      </axis>
    </joint>
    <link name='only_ezgripper_finger_tip_2'>
      <pose frame=''>0.1711 -0.03 0 -1.5708 -1e-06 2.88159</pose>
      <inertial>
        <pose frame=''>-0.03108 0 -0.00325 0 -0 0</pose>
        <mass>0.025</mass>
        <inertia>
          <ixx>0.01</ixx>
          <ixy>0</ixy>
          <ixz>0</ixz>
          <iyy>0.01</iyy>
          <iyz>0</iyz>
          <izz>0.01</izz>
        </inertia>
      </inertial>
      <collision name='only_ezgripper_finger_tip_2_collision'>
        <pose frame=''>0 0 0 0 -0 0</pose>
        <geometry>
          <mesh>
            <scale>1 1 1</scale>
            <uri>model://ezgripper_driver/meshes/collision/SAKE_Finger_Link2.stl</uri>
          </mesh>
        </geometry>
      </collision>
      <visual name='only_ezgripper_finger_tip_2_visual'>
        <pose frame=''>0 0 0 0 -0 0</pose>
        <geometry>
          <mesh>
            <scale>1 1 1</scale>
            <uri>model://ezgripper_driver/meshes/visual/SAKE_Finger_Link2.stl</uri>
          </mesh>
        </geometry>
      </visual>
    </link>
    <joint name='only_ezgripper_tip_joint_2' type='revolute'>
      <child>only_ezgripper_finger_tip_2</child>
      <parent>only_ezgripper_finger_2</parent>
      <axis>
        <xyz>0 4e-06 -1</xyz>
        <limit>
          <lower>-1.57</lower>
          <upper>0.26</upper>
          <effort>1</effort>
          <velocity>3.67</velocity>
        </limit>
        <dynamics>
          <damping>0.1</damping>
          <friction>0</friction>
          <spring_reference>0.31</spring_reference>
          <spring_stiffness>0.2</spring_stiffness>
        </dynamics>
        <use_parent_model_frame>1</use_parent_model_frame>
      </axis>
    </joint>
    <link name='spring_force_calculation_link'>
      <pose frame=''>0 0 0.063 0 -0 0</pose>
      <inertial>
        <pose frame=''>0.005 0.005 0.005 0 -0 0</pose>
        <mass>0.05</mass>
        <inertia>
          <ixx>0.01</ixx>
          <ixy>0</ixy>
          <ixz>0</ixz>
          <iyy>0.01</iyy>
          <iyz>0</iyz>
          <izz>0.01</izz>
        </inertia>
      </inertial>
      <visual name='spring_force_calculation_link_visual'>
        <pose frame=''>0 0 0 0 -0 0</pose>
        <geometry>
          <box>
            <size>0.01 0.01 0.01</size>
          </box>
        </geometry>
      </visual>
    </link>
    <joint name='spring_force_calculation_joint' type='revolute'>
      <child>spring_force_calculation_link</child>
      <parent>only_ezgripper_palm_link</parent>
      <axis>
        <xyz>0 1 0</xyz>
        <limit>
          <lower>-0.27</lower>
          <upper>1.57075</upper>
          <effort>1</effort>
          <velocity>3.67</velocity>
        </limit>
        <dynamics>
          <damping>0.1</damping>
          <friction>0</friction>
          <spring_reference>1.57075</spring_reference>
          <spring_stiffness>0.1</spring_stiffness>
        </dynamics>
        <use_parent_model_frame>1</use_parent_model_frame>
      </axis>
    </joint>
    <plugin name='gazebo_ros_control' filename='libgazebo_ros_control.so'/>
    <static>0</static>
    <plugin name='joint_state_publisher' filename='libgazebo_ros_joint_state_publisher.so'>
      <jointName>only_ezgripper_knuckle_1, only_ezgripper_knuckle_2, only_ezgripper_tip_joint_1, only_ezgripper_tip_joint_2, spring_force_calculation_joint, base_x, base_y, base_z, base_rx, base_ry, base_rz</jointName>
    </plugin>
    <self_collide>true</self_collide>
  </model>
</sdf>
