<?xml version="1.0" ?>
<!-- =================================================================================== -->
<!-- |    This document was autogenerated by xacro from ezgripper_dual_standalone.urdf.xacro | -->
<!-- |    EDITING THIS FILE BY HAND IS NOT RECOMMENDED                                 | -->
<!-- =================================================================================== -->
<robot name="ezgripper_stand_alone" xmlns:xacro="http://www.ros.org/wiki/xacro">
  <!--macro name="ezgripper" params="*origin"-->
  <!-- joints -->
  <!-- transmissions for Gazebo -->
  <gazebo>
    <plugin filename="libgazebo_ros_control.so" name="gazebo_ros_control">
    </plugin>
  </gazebo>

  <gazebo>
    <plugin name="joint_state_publisher" filename="libgazebo_ros_joint_state_publisher.so">
      <jointName>
        only_ezgripper_knuckle_1,
        only_ezgripper_knuckle_2,
        only_ezgripper_tip_joint_1,
        only_ezgripper_tip_joint_2,
        spring_force_calculation_joint,
        base_x,
        base_y,
        base_z,
        base_rx,
        base_ry,
        base_rz
      </jointName>
    </plugin>
  </gazebo>

  <!-- Add the gripper -->
  <!-- links -->
  <link name="world"/>

  <link name="ezgripper_xy">
    <inertial>
      <origin xyz="0 0 0" rpy="0 0 0"/>
      <mass value="1"/>
      <inertia
        ixx="1.0" ixy="0.0" ixz="0.0"
        iyy="1.0" iyz="0.0"
        izz="1.0"/>
    </inertial>
  </link>
  <link name="ezgripper_yz">
    <inertial>
      <origin xyz="0 0 0" rpy="0 0 0"/>
      <mass value="1"/>
      <inertia
        ixx="1.0" ixy="0.0" ixz="0.0"
        iyy="1.0" iyz="0.0"
        izz="1.0"/>
    </inertial>
  </link>
  <link name="ezgripper_z_rx">
    <inertial>
      <origin xyz="0 0 0" rpy="0 0 0"/>
      <mass value="1"/>
      <inertia
        ixx="1.0" ixy="0.0" ixz="0.0"
        iyy="1.0" iyz="0.0"
        izz="1.0"/>
    </inertial>
  </link>
  <link name="ezgripper_rx_ry">
    <inertial>
      <origin xyz="0 0 0" rpy="0 0 0"/>
      <mass value="1"/>
      <inertia
        ixx="1.0" ixy="0.0" ixz="0.0"
        iyy="1.0" iyz="0.0"
        izz="1.0"/>
    </inertial>
  </link>
  <link name="ezgripper_ry_rz">
    <inertial>
      <origin xyz="0 0 0" rpy="0 0 0"/>
      <mass value="1"/>
      <inertia
        ixx="1.0" ixy="0.0" ixz="0.0"
        iyy="1.0" iyz="0.0"
        izz="1.0"/>
    </inertial>
  </link>

  <joint name="base_x" type="prismatic">
    <origin rpy="0 0 0" xyz="0.0 0.0 0"/>
    <parent link="world"/>
    <child link="ezgripper_xy"/>
    <axis xyz="1 0 0"/>
    <limit effort="100" lower="-10" upper="10" velocity="2"/>
  </joint>
  <joint name="base_y" type="prismatic">
    <origin rpy="0 0 0" xyz="0.0 0.0 0"/>
    <parent link="ezgripper_xy"/>
    <child link="ezgripper_yz"/>
    <axis xyz="0 1 0"/>
    <limit effort="100" lower="-10" upper="10" velocity="2"/>
  </joint>
  <joint name="base_z" type="prismatic">
    <origin rpy="0 0 0" xyz="0.0 0.0 0"/>
    <parent link="ezgripper_yz"/>
    <child link="ezgripper_z_rx"/>
    <axis xyz="0 0 1"/>
    <limit effort="100" lower="-10" upper="10" velocity="2"/>
  </joint>
  <joint name="base_rx" type="revolute">
    <origin rpy="0 0 0" xyz="0.0 0.0 0"/>
    <parent link="ezgripper_z_rx"/>
    <child link="ezgripper_rx_ry"/>
    <axis xyz="1 0 0"/>
    <limit effort="100" lower="-3.1415" upper="3.1415" velocity="2"/>
  </joint>
  <joint name="base_ry" type="revolute">
    <origin rpy="0 0 0" xyz="0.0 0.0 0"/>
    <parent link="ezgripper_rx_ry"/>
    <child link="ezgripper_ry_rz"/>
    <axis xyz="0 1 0"/>
    <limit effort="100" lower="-3.1415" upper="3.1415" velocity="2"/>
  </joint>
  <joint name="base_rz" type="revolute">
    <origin rpy="0 0 0" xyz="0 0 0"/>
    <parent link="ezgripper_ry_rz"/>
    <child link="only_ezgripper_palm_link"/>
    <axis xyz="0 0 1"/>
    <limit effort="100" lower="-3.1415" upper="3.1415" velocity="2"/>
  </joint>

  <link name="only_ezgripper_palm_link">
    <visual>
      <origin rpy="0 0 0" xyz="0 0 0"/>
      <geometry>
        <mesh filename="package://ezgripper_driver/meshes/visual/SAKE_Palm_Dual.stl"/>
      </geometry>
    </visual>
    <collision>
      <origin rpy="0 0 0" xyz="0 0 0"/>
      <geometry>
        <mesh filename="package://ezgripper_driver/meshes/collision/SAKE_Palm_Dual.stl"/>
      </geometry>
    </collision>
    <inertial>
      <origin rpy="0 0 0" xyz="0 0 0"/>
      <mass value=".3"/>
      <inertia ixx="0.01" ixy="0.0" ixz="0.0" iyy="0.01" iyz="0.0" izz="0.01"/>
    </inertial>
  </link>

  <link name="only_ezgripper_kinect_link">
    <inertial>
      <origin xyz="0 0 0" />
      <mass value="0.01" />
      <inertia  ixx="0.01" ixy="0.0"  ixz="0.0"  iyy="0.01"  iyz="0.0"  izz="0.01" />
    </inertial>
    <visual>
      <origin xyz="0 0 0" />
      <geometry>
        <box size="0.01 0.02 0.01" />
      </geometry>
    </visual>
  </link>

  <joint name="only_ezgripper_kinect_link" type="fixed">
    <origin rpy="0 0.5 0" xyz="0 0 0.17"/>
    <parent link="only_ezgripper_palm_link"/>
    <child link="only_ezgripper_kinect_link"/>
  </joint>

  <gazebo reference="only_ezgripper_kinect_link">
    <material>Gazebo/Red</material>
  </gazebo>

  <link name="only_ezgripper_finger_1">
    <visual>
      <origin rpy="0 0 0" xyz="0 0 0"/>
      <geometry>
        <mesh filename="package://ezgripper_driver/meshes/visual/SAKE_Finger_Link1.stl"/>
      </geometry>
    </visual>
    <collision>
      <origin rpy="0 0 0" xyz="0 0 0"/>
      <geometry>
        <mesh filename="package://ezgripper_driver/meshes/collision/SAKE_Finger_Link1.stl"/>
      </geometry>
    </collision>
    <inertial>
      <origin rpy="0 0 0" xyz="-0.03121 0 -0.00256"/>
      <mass value=".025"/>
      <inertia ixx="0.01" ixy="0.0" ixz="0.0" iyy="0.01" iyz="0.0" izz="0.01"/>
    </inertial>
  </link>

  <link name="only_ezgripper_finger_2">
    <visual>
      <origin rpy="0 0 0" xyz="0 0 0"/>
      <geometry>
        <mesh filename="package://ezgripper_driver/meshes/visual/SAKE_Finger_Link1.stl"/>
      </geometry>
    </visual>
    <collision>
      <origin rpy="0 0 0" xyz="0 0 0"/>
      <geometry>
        <mesh filename="package://ezgripper_driver/meshes/collision/SAKE_Finger_Link1.stl"/>
      </geometry>
    </collision>
    <inertial>
      <origin rpy="0 0 0" xyz="-0.03121 0 -0.00256"/>
      <mass value=".025"/>
      <inertia ixx="0.01" ixy="0.0" ixz="0.0" iyy="0.01" iyz="0.0" izz="0.01"/>
    </inertial>
  </link>

  <joint name="only_ezgripper_knuckle_1" type="revolute">
    <parent link="only_ezgripper_palm_link"/>
    <child link="only_ezgripper_finger_1"/>
    <origin rpy="1.5708 0 3.14159" xyz="0.1056 0.03 0"/>
    <axis xyz="0 1 0"/>
    <limit effort="1" lower="-.27" upper="1.57075" velocity="3.67"/>
    <dynamics damping="0.1" />
  </joint>

  <joint name="only_ezgripper_knuckle_2" type="revolute">
    <parent link="only_ezgripper_palm_link"/>
    <child link="only_ezgripper_finger_2"/>
    <origin rpy="-1.5708 0 3.14159" xyz="0.1056 -0.03 0"/>
    <axis xyz="0 1 0"/>
    <limit effort="1" lower="-.27" upper="1.57075" velocity="3.67"/>
    <dynamics damping="0.1" />
  </joint>

  <link name="only_ezgripper_finger_tip_1">
    <visual>
      <origin rpy="0 0 0" xyz="0 0 0"/>
      <geometry>
        <mesh filename="package://ezgripper_driver/meshes/visual/SAKE_Finger_Link2.stl"/>
      </geometry>
    </visual>
    <collision>
      <origin rpy="0 0 0" xyz="0 0 0"/>
      <geometry>
        <mesh filename="package://ezgripper_driver/meshes/collision/SAKE_Finger_Link2.stl"/>
      </geometry>
    </collision>
    <inertial>
      <origin rpy="0 0 0" xyz="-0.03108 0 -0.00325"/>
      <mass value=".025"/>
      <inertia ixx="0.01" ixy="0.0" ixz="0.0" iyy="0.01" iyz="0.0" izz="0.01"/>
    </inertial>
  </link>

  <link name="only_ezgripper_finger_tip_2">
    <visual>
      <origin rpy="0 0 0" xyz="0 0 0"/>
      <geometry>
        <mesh filename="package://ezgripper_driver/meshes/visual/SAKE_Finger_Link2.stl"/>
      </geometry>
    </visual>
    <collision>
      <origin rpy="0 0 0" xyz="0 0 0"/>
      <geometry>
        <mesh filename="package://ezgripper_driver/meshes/collision/SAKE_Finger_Link2.stl"/>
      </geometry>
    </collision>
    <inertial>
      <origin rpy="0 0 0" xyz="-0.03108 0 -0.00325"/>
      <mass value=".025"/>
      <inertia ixx="0.01" ixy="0.0" ixz="0.0" iyy="0.01" iyz="0.0" izz="0.01"/>
    </inertial>
  </link>

  <joint name="only_ezgripper_tip_joint_1" type="revolute">
    <parent link="only_ezgripper_finger_1"/>
    <child link="only_ezgripper_finger_tip_1"/>
    <origin rpy="0 0.26 0" xyz="-0.0655 0 0"/>
    <axis xyz="0 1 0"/>
    <limit effort="1" lower="-1.57" upper="0.26" velocity="3.67"/>
    <dynamics damping="0.1" />
  </joint>

  <joint name="only_ezgripper_tip_joint_2" type="revolute">
    <parent link="only_ezgripper_finger_2"/>
    <child link="only_ezgripper_finger_tip_2"/>
    <origin rpy="0 0.26 0" xyz="-0.0655 0 0"/>
    <axis xyz="0 1 0"/>
    <limit effort="1" lower="-1.57" upper="0.26" velocity="3.67"/>
    <dynamics damping="0.1" />
  </joint>

  <link name="spring_force_calculation_link">
    <visual>
      <origin rpy="0 0 0" xyz="0 0 0"/>
      <geometry>
        <box size="0.01 0.01 0.01">
        </box>
      </geometry>
    </visual>
    <inertial>
      <origin rpy="0 0 0" xyz="0.005 0.005 0.005"/>
      <mass value=".05"/>
      <inertia ixx="0.01" ixy="0.0" ixz="0.0" iyy="0.01" iyz="0.0" izz="0.01"/>
    </inertial>
  </link>

  <joint name="spring_force_calculation_joint" type="revolute">
    <parent link="only_ezgripper_palm_link"/>
    <child link="spring_force_calculation_link"/>
    <origin rpy="0 0 0" xyz="0 0 0.063"/>
    <axis xyz="0 1 0"/>
    <limit effort="1" lower="-.27" upper="1.57075" velocity="3.67"/>
    <dynamics damping="0.1" />
  </joint>

  <transmission name="only_ezgripper_trans_1">
    <type>transmission_interface/SimpleTransmission</type>
    <joint name="only_ezgripper_knuckle_1">
      <hardwareInterface>EffortJointInterface</hardwareInterface>
    </joint>
    <actuator name="only_ezgripper_motor1">
      <mechanicalReduction>1</mechanicalReduction>
    </actuator>
  </transmission>

  <transmission name="only_ezgripper_trans_2">
    <type>transmission_interface/SimpleTransmission</type>
    <joint name="only_ezgripper_knuckle_2">
      <hardwareInterface>EffortJointInterface</hardwareInterface>
    </joint>
    <actuator name="only_ezgripper_motor2">
      <mechanicalReduction>1</mechanicalReduction>
    </actuator>
  </transmission>

  <transmission name="only_ezgripper_trans_3">
    <type>transmission_interface/SimpleTransmission</type>
    <joint name="only_ezgripper_tip_joint_1">
      <hardwareInterface>EffortJointInterface</hardwareInterface>
    </joint>
    <actuator name="only_ezgripper_motor3">
      <mechanicalReduction>1</mechanicalReduction>
    </actuator>
  </transmission>

  <transmission name="only_ezgripper_trans_4">
    <type>transmission_interface/SimpleTransmission</type>
    <joint name="only_ezgripper_tip_joint_2">
      <hardwareInterface>EffortJointInterface</hardwareInterface>
    </joint>
    <actuator name="only_ezgripper_motor4">
      <mechanicalReduction>1</mechanicalReduction>
    </actuator>
  </transmission>

  <transmission name="only_ezgripper_trans_5">
    <type>transmission_interface/SimpleTransmission</type>
    <joint name="spring_force_calculation_joint">
      <hardwareInterface>EffortJointInterface</hardwareInterface>
    </joint>
    <actuator name="only_ezgripper_motor5">
      <mechanicalReduction>1</mechanicalReduction>
    </actuator>
  </transmission>

  <transmission name="only_ezgripper_trans_x">
    <type>transmission_interface/SimpleTransmission</type>
    <joint name="base_x">
      <hardwareInterface>EffortJointInterface</hardwareInterface>
    </joint>
    <actuator name="only_ezgripper_motor6">
      <mechanicalReduction>1</mechanicalReduction>
    </actuator>
  </transmission>

  <transmission name="only_ezgripper_trans_y">
    <type>transmission_interface/SimpleTransmission</type>
    <joint name="base_y">
      <hardwareInterface>EffortJointInterface</hardwareInterface>
    </joint>
    <actuator name="only_ezgripper_motor6">
      <mechanicalReduction>1</mechanicalReduction>
    </actuator>
  </transmission>

  <transmission name="only_ezgripper_trans_z">
    <type>transmission_interface/SimpleTransmission</type>
    <joint name="base_z">
      <hardwareInterface>EffortJointInterface</hardwareInterface>
    </joint>
    <actuator name="only_ezgripper_motor6">
      <mechanicalReduction>1</mechanicalReduction>
    </actuator>
  </transmission>

  <transmission name="only_ezgripper_trans_rx">
    <type>transmission_interface/SimpleTransmission</type>
    <joint name="base_rx">
      <hardwareInterface>EffortJointInterface</hardwareInterface>
    </joint>
    <actuator name="only_ezgripper_motor6">
      <mechanicalReduction>1</mechanicalReduction>
    </actuator>
  </transmission>

  <transmission name="only_ezgripper_trans_ry">
    <type>transmission_interface/SimpleTransmission</type>
    <joint name="base_ry">
      <hardwareInterface>EffortJointInterface</hardwareInterface>
    </joint>
    <actuator name="only_ezgripper_motor6">
      <mechanicalReduction>1</mechanicalReduction>
    </actuator>
  </transmission>

  <transmission name="only_ezgripper_trans_rz">
    <type>transmission_interface/SimpleTransmission</type>
    <joint name="base_rz">
      <hardwareInterface>EffortJointInterface</hardwareInterface>
    </joint>
    <actuator name="only_ezgripper_motor6">
      <mechanicalReduction>1</mechanicalReduction>
    </actuator>
  </transmission>

  <!-- https://github.com/qboticslabs/mastering_ros_robot_description_pkg/blob/master/urdf/seven_dof_arm.urdf -->
  <gazebo reference="only_ezgripper_kinect_link">
    <!-- Depth (IR) -->
    <sensor name="rgbd_camera_frame_sensor" type="depth">
      <always_on>true</always_on>
      <update_rate>6.0</update_rate>
      <camera>
        <horizontal_fov>1.01229096616</horizontal_fov>
        <image>
          <width>320</width>
          <height>240</height>
        </image>
        <clip>
          <near>0.05</near>
          <far>4.0</far>
        </clip>
      </camera>
      <plugin filename="libgazebo_ros_openni_kinect.so" name="rgbd_camera_frame_controller">
        <alwaysOn>true</alwaysOn>
        <updateRate>6.0</updateRate>
        <cameraName>camera</cameraName>
        <imageTopicName>ir/image_raw</imageTopicName>
        <cameraInfoTopicName>ir/camera_info</cameraInfoTopicName>
        <depthImageTopicName>depth_registered/sw_registered/image_rect_raw</depthImageTopicName>
        <depthImageCameraInfoTopicName>depth/camera_info</depthImageCameraInfoTopicName>
        <pointCloudTopicName>/overhead_kinect1/depth_registered/points</pointCloudTopicName>
        <frameName>kinect_frame</frameName>
        <pointCloudCutoff>0.05</pointCloudCutoff>
        <pointCloudCutoffMax>5</pointCloudCutoffMax>
        <rangeMax>4.0</rangeMax>
        <!-- Distortion parameters not supported in gazebo 1.9.* plugins -->
        <!--distortionK1>0.00000001</distortionK1>
          <distortionK2>0.00000001</distortionK2>
          <distortionK3>0.00000001</distortionK3>
          <distortionT1>0.00000001</distortionT1>
          <distortionT2>0.00000001</distortionT2-->
      </plugin>
    </sensor>
  </gazebo>


</robot>

