<?xml version="1.0" ?>
<!-- =================================================================================== -->
<!-- |    This document was autogenerated by xacro from ezgripper_dual_standalone.urdf.xacro | -->
<!-- |    EDITING THIS FILE BY HAND IS NOT RECOMMENDED                                 | -->
<!-- =================================================================================== -->
<robot name="ezgripper_stand_alone" xmlns:xacro="http://www.ros.org/wiki/xacro">
  <!--macro name="ezgripper" params="*origin"-->
  <!-- joints -->
  <!-- transmissions for Gazebo -->
  <gazebo>
    <plugin filename="libgazebo_ros_control.so" name="gazebo_ros_control">
   </plugin>
  </gazebo>

  <gazebo reference="only_ezgripper_knuckle_1">
    <stopCfm>0.8</stopCfm>
    <stopErp>100</stopErp>
    <provideFeedback>true</provideFeedback>
    <implicitSpringDamper>true</implicitSpringDamper>
    <fudgeFactor>0.2</fudgeFactor>
  </gazebo>

  <gazebo reference="only_ezgripper_knuckle_2">
    <stopCfm>0.8</stopCfm>
    <stopErp>100</stopErp>
    <provideFeedback>true</provideFeedback>
    <implicitSpringDamper>true</implicitSpringDamper>
    <fudgeFactor>0.2</fudgeFactor>
  </gazebo>

  <!-- Add the gripper -->
  <!-- links -->
  <link name="world"/>
  <joint name="fixed" type="fixed">
    <origin rpy="0 0 0" xyz="0.049 0.0 0.2"/>
    <parent link="world"/>
    <child link="only_ezgripper_palm_link"/>
    <axis xyz="0 0 0"/>
  </joint>

  <link name="only_ezgripper_palm_link">
    <visual>
      <origin rpy="0 0 0" xyz="0 0 0"/>
      <geometry>
        <mesh filename="package://ezgripper_driver/meshes/visual/SAKE_Palm_Dual.stl"/>
      </geometry>
    </visual>
    <collision>
      <origin rpy="0 0 0" xyz="0 0 0"/>
      <geometry>
        <mesh filename="package://ezgripper_driver/meshes/collision/SAKE_Palm_Dual.stl"/>
      </geometry>
    </collision>
    <inertial>
      <origin rpy="0 0 0" xyz="0 0 0"/>
      <mass value=".3"/>
      <inertia ixx="0.01" ixy="0.0" ixz="0.0" iyy="0.01" iyz="0.0" izz="0.01"/>
    </inertial>
  </link>

  <link name="only_ezgripper_finger_1">
    <visual>
      <origin rpy="0 0 0" xyz="0 0 0"/>
      <geometry>
        <mesh filename="package://ezgripper_driver/meshes/visual/SAKE_Finger.stl"/>
      </geometry>
    </visual>
    <collision>
      <origin rpy="0 0 0" xyz="0 0 0"/>
      <geometry>
        <mesh filename="package://ezgripper_driver/meshes/collision/SAKE_Finger.stl"/>
      </geometry>
    </collision>
    <inertial>
      <origin rpy="0 0 0" xyz="-0.064 0 0.00132"/>
      <mass value=".025"/>
      <inertia ixx="0.01" ixy="0.0" ixz="0.0" iyy="0.01" iyz="0.0" izz="0.01"/>
    </inertial>
  </link>

  <link name="only_ezgripper_finger_2">
    <visual>
      <origin rpy="0 0 0" xyz="0 0 0"/>
      <geometry>
        <mesh filename="package://ezgripper_driver/meshes/visual/SAKE_Finger.stl"/>
      </geometry>
    </visual>
    <collision>
      <origin rpy="0 0 0" xyz="0 0 0"/>
      <geometry>
        <mesh filename="package://ezgripper_driver/meshes/collision/SAKE_Finger.stl"/>
      </geometry>
    </collision>
    <inertial>
      <origin rpy="0 0 0" xyz="-0.064 0 0.00132"/>
      <mass value=".025"/>
      <inertia ixx="0.01" ixy="0.0" ixz="0.0" iyy="0.01" iyz="0.0" izz="0.01"/>
    </inertial>
  </link>

  <joint name="only_ezgripper_knuckle_1" type="revolute">
    <parent link="only_ezgripper_palm_link"/>
    <child link="only_ezgripper_finger_1"/>
    <origin rpy="1.5708 0 3.14159" xyz="0.1056 0.03 0"/>
    <axis xyz="0 1 0"/>
    <limit effort="1" lower="-.27" upper="1.57075" velocity="3.67"/>
  </joint>

  <joint name="only_ezgripper_knuckle_2" type="revolute">
    <parent link="only_ezgripper_palm_link"/>
    <child link="only_ezgripper_finger_2"/>
    <origin rpy="-1.5708 0 3.14159" xyz="0.1056 -0.03 0"/>
    <axis xyz="0 1 0"/>
    <limit effort="1" lower="-.27" upper="1.57075" velocity="3.67"/>
    <mimic joint="ezgripper_knuckle_1"/>
  </joint>

  <transmission name="only_ezgripper_trans_1">
    <type>transmission_interface/SimpleTransmission</type>
    <joint name="only_ezgripper_knuckle_1">
      <hardwareInterface>EffortJointInterface</hardwareInterface>
    </joint>
    <actuator name="only_ezgripper_motor1">
      <mechanicalReduction>1</mechanicalReduction>
      <hardwareInterface>EffortJointInterface</hardwareInterface>
    </actuator>
  </transmission>

  <transmission name="only_ezgripper_trans_2">
    <type>transmission_interface/SimpleTransmission</type>
    <joint name="only_ezgripper_knuckle_2">
      <hardwareInterface>EffortJointInterface</hardwareInterface>
    </joint>
    <actuator name="only_ezgripper_motor2">
      <mechanicalReduction>1</mechanicalReduction>
      <hardwareInterface>EffortJointInterface</hardwareInterface>
    </actuator>
  </transmission>

</robot>

