<sdf version='1.6'>
  <model name='ezgripper_stand_alone'>
    <link name='only_ezgripper_palm_link'>
      <pose frame=''>0.049 0 0.2 0 -0 0</pose>
      <inertial>
        <pose frame=''>0 0 0 0 -0 0</pose>
        <mass>0.3</mass>
        <inertia>
          <ixx>0.01</ixx>
          <ixy>0</ixy>
          <ixz>0</ixz>
          <iyy>0.01</iyy>
          <iyz>0</iyz>
          <izz>0.01</izz>
        </inertia>
      </inertial>
      <collision name='only_ezgripper_palm_link_collision'>
        <pose frame=''>0 0 0 0 -0 0</pose>
        <geometry>
          <mesh>
            <scale>1 1 1</scale>
            <uri>model://ezgripper_driver/meshes/collision/SAKE_Palm_Dual.stl</uri>
          </mesh>
        </geometry>
      </collision>
      <visual name='only_ezgripper_palm_link_visual'>
        <pose frame=''>0 0 0 0 -0 0</pose>
        <geometry>
          <mesh>
            <scale>1 1 1</scale>
            <uri>model://ezgripper_driver/meshes/visual/SAKE_Palm_Dual.stl</uri>
          </mesh>
        </geometry>
      </visual>
    </link>
    <joint name='robot_base' type='revolute'>
      <child>only_ezgripper_palm_link</child>
      <parent>world</parent>
      <axis>
        <limit>
          <lower>0</lower>
          <upper>0</upper>
        </limit>
        <dynamics>
          <damping>0</damping>
          <friction>0</friction>
          <spring_reference>0</spring_reference>
          <spring_stiffness>0</spring_stiffness>
        </dynamics>
        <use_parent_model_frame>1</use_parent_model_frame>
        <xyz>0 0 1</xyz>
      </axis>
    </joint>
    <link name='only_ezgripper_finger_1'>
      <pose frame=''>0.1546 0.03 0.2 1.5708 -0 3.14159</pose>
      <inertial>
        <pose frame=''>-0.03121 0 -0.00256 0 -0 0</pose>
        <mass>0.025</mass>
        <inertia>
          <ixx>0.01</ixx>
          <ixy>0</ixy>
          <ixz>0</ixz>
          <iyy>0.01</iyy>
          <iyz>0</iyz>
          <izz>0.01</izz>
        </inertia>
      </inertial>
      <collision name='only_ezgripper_finger_1_collision'>
        <pose frame=''>0 0 0 0 -0 0</pose>
        <geometry>
          <mesh>
            <scale>1 1 1</scale>
            <uri>model://ezgripper_driver/meshes/collision/SAKE_Finger_Link1.stl</uri>
          </mesh>
        </geometry>
      </collision>
      <visual name='only_ezgripper_finger_1_visual'>
        <pose frame=''>0 0 0 0 -0 0</pose>
        <geometry>
          <mesh>
            <scale>1 1 1</scale>
            <uri>model://ezgripper_driver/meshes/visual/SAKE_Finger_Link1.stl</uri>
          </mesh>
        </geometry>
      </visual>
    </link>
    <joint name='only_ezgripper_knuckle_1' type='revolute'>
      <child>only_ezgripper_finger_1</child>
      <parent>only_ezgripper_palm_link</parent>
      <axis>
        <xyz>0 4e-06 1</xyz>
        <limit>
          <lower>-0.27</lower>
          <upper>1.57075</upper>
          <effort>1</effort>
          <velocity>3.67</velocity>
        </limit>
        <dynamics>
          <damping>0.1</damping>
          <spring_reference>1.57075</spring_reference>
          <spring_stiffness>0.1</spring_stiffness>
        </dynamics>
        <use_parent_model_frame>1</use_parent_model_frame>
      </axis>
    </joint>
    <link name='only_ezgripper_finger_tip_1'>
      <pose frame=''>0.2201 0.03 0.2 1.5708 -1e-06 -2.8316</pose>
      <inertial>
        <pose frame=''>-0.03108 0 -0.00325 0 -0 0</pose>
        <mass>0.025</mass>
        <inertia>
          <ixx>0.01</ixx>
          <ixy>0</ixy>
          <ixz>0</ixz>
          <iyy>0.01</iyy>
          <iyz>0</iyz>
          <izz>0.01</izz>
        </inertia>
      </inertial>
      <collision name='only_ezgripper_finger_tip_1_collision'>
        <pose frame=''>0 0 0 0 -0 0</pose>
        <geometry>
          <mesh>
            <scale>1 1 1</scale>
            <uri>model://ezgripper_driver/meshes/collision/SAKE_Finger_Link2.stl</uri>
          </mesh>
        </geometry>
      </collision>
      <visual name='only_ezgripper_finger_tip_1_visual'>
        <pose frame=''>0 0 0 0 -0 0</pose>
        <geometry>
          <mesh>
            <scale>1 1 1</scale>
            <uri>model://ezgripper_driver/meshes/visual/SAKE_Finger_Link2.stl</uri>
          </mesh>
        </geometry>
      </visual>
    </link>
    <joint name='only_ezgripper_tip_joint_1' type='revolute'>
      <child>only_ezgripper_finger_tip_1</child>
      <parent>only_ezgripper_finger_1</parent>
      <axis>
        <xyz>0 4e-06 1</xyz>
        <limit>
          <lower>-1.57</lower>
          <upper>0.31</upper>
          <effort>1</effort>
          <velocity>3.67</velocity>
        </limit>
        <dynamics>
          <damping>0.1</damping>
          <spring_reference>0.31</spring_reference>
          <spring_stiffness>0.2</spring_stiffness>
        </dynamics>
        <use_parent_model_frame>1</use_parent_model_frame>
      </axis>
    </joint>
    <link name='only_ezgripper_finger_2'>
      <pose frame=''>0.1546 -0.03 0.2 -1.5708 -0 3.14159</pose>
      <inertial>
        <pose frame=''>-0.03121 0 -0.00256 0 -0 0</pose>
        <mass>0.025</mass>
        <inertia>
          <ixx>0.01</ixx>
          <ixy>0</ixy>
          <ixz>0</ixz>
          <iyy>0.01</iyy>
          <iyz>0</iyz>
          <izz>0.01</izz>
        </inertia>
      </inertial>
      <collision name='only_ezgripper_finger_2_collision'>
        <pose frame=''>0 0 0 0 -0 0</pose>
        <geometry>
          <mesh>
            <scale>1 1 1</scale>
            <uri>model://ezgripper_driver/meshes/collision/SAKE_Finger_Link1.stl</uri>
          </mesh>
        </geometry>
      </collision>
      <visual name='only_ezgripper_finger_2_visual'>
        <pose frame=''>0 0 0 0 -0 0</pose>
        <geometry>
          <mesh>
            <scale>1 1 1</scale>
            <uri>model://ezgripper_driver/meshes/visual/SAKE_Finger_Link1.stl</uri>
          </mesh>
        </geometry>
      </visual>
    </link>
    <joint name='only_ezgripper_knuckle_2' type='revolute'>
      <child>only_ezgripper_finger_2</child>
      <parent>only_ezgripper_palm_link</parent>
      <axis>
        <xyz>0 4e-06 -1</xyz>
        <limit>
          <lower>-0.27</lower>
          <upper>1.57075</upper>
          <effort>1</effort>
          <velocity>3.67</velocity>
        </limit>
        <dynamics>
          <damping>0.1</damping>
          <spring_reference>1.57075</spring_reference>
          <spring_stiffness>0.1</spring_stiffness>
        </dynamics>
        <use_parent_model_frame>1</use_parent_model_frame>
      </axis>
    </joint>
    <link name='only_ezgripper_finger_tip_2'>
      <pose frame=''>0.2201 -0.03 0.2 -1.5708 -1e-06 2.83159</pose>
      <inertial>
        <pose frame=''>-0.03108 0 -0.00325 0 -0 0</pose>
        <mass>0.025</mass>
        <inertia>
          <ixx>0.01</ixx>
          <ixy>0</ixy>
          <ixz>0</ixz>
          <iyy>0.01</iyy>
          <iyz>0</iyz>
          <izz>0.01</izz>
        </inertia>
      </inertial>
      <collision name='only_ezgripper_finger_tip_2_collision'>
        <pose frame=''>0 0 0 0 -0 0</pose>
        <geometry>
          <mesh>
            <scale>1 1 1</scale>
            <uri>model://ezgripper_driver/meshes/collision/SAKE_Finger_Link2.stl</uri>
          </mesh>
        </geometry>
      </collision>
      <visual name='only_ezgripper_finger_tip_2_visual'>
        <pose frame=''>0 0 0 0 -0 0</pose>
        <geometry>
          <mesh>
            <scale>1 1 1</scale>
            <uri>model://ezgripper_driver/meshes/visual/SAKE_Finger_Link2.stl</uri>
          </mesh>
        </geometry>
      </visual>
    </link>
    <joint name='only_ezgripper_tip_joint_2' type='revolute'>
      <child>only_ezgripper_finger_tip_2</child>
      <parent>only_ezgripper_finger_2</parent>
      <axis>
        <xyz>0 4e-06 -1</xyz>
        <limit>
          <lower>-1.57</lower>
          <upper>0.31</upper>
          <effort>1</effort>
          <velocity>3.67</velocity>
        </limit>
        <dynamics>
          <damping>0.1</damping>
          <spring_reference>0.31</spring_reference>
          <spring_stiffness>0.2</spring_stiffness>
        </dynamics>
        <use_parent_model_frame>1</use_parent_model_frame>
      </axis>
    </joint>
    <link name='spring_force_calculation_link'>
      <pose frame=''>0.049 0 0.263 0 -0 0</pose>
      <inertial>
        <pose frame=''>0.005 0.005 0.005 0 -0 0</pose>
        <mass>0.05</mass>
        <inertia>
          <ixx>0.01</ixx>
          <ixy>0</ixy>
          <ixz>0</ixz>
          <iyy>0.01</iyy>
          <iyz>0</iyz>
          <izz>0.01</izz>
        </inertia>
      </inertial>
      <visual name='spring_force_calculation_link_visual'>
        <pose frame=''>0 0 0 0 -0 0</pose>
        <geometry>
          <box>
            <size>0.01 0.01 0.01</size>
          </box>
        </geometry>
      </visual>
    </link>
    <joint name='spring_force_calculation_joint' type='revolute'>
      <child>spring_force_calculation_link</child>
      <parent>only_ezgripper_palm_link</parent>
      <axis>
        <xyz>0 1 0</xyz>
        <limit>
          <lower>-0.27</lower>
          <upper>1.57075</upper>
          <effort>1</effort>
          <velocity>3.67</velocity>
        </limit>
        <dynamics>
          <damping>0.1</damping>
          <spring_reference>1.57075</spring_reference>
          <spring_stiffness>0.1</spring_stiffness>
        </dynamics>
        <use_parent_model_frame>1</use_parent_model_frame>
      </axis>
    </joint>
    <plugin name='gazebo_ros_control' filename='libgazebo_ros_control.so'/>
    <static>0</static>
    <plugin name='joint_state_publisher' filename='libgazebo_ros_joint_state_publisher.so'>
      <jointName>
        only_ezgripper_knuckle_1,
        only_ezgripper_knuckle_2,
        only_ezgripper_tip_joint_1,
        only_ezgripper_tip_joint_2,
        spring_force_calculation_joint
      </jointName>
    </plugin>
  </model>
</sdf>
