<?xml version="1.0" ?>
<!-- =================================================================================== -->
<!-- |    This document was autogenerated by xacro from ezgripper_dual_standalone.urdf.xacro | -->
<!-- |    EDITING THIS FILE BY HAND IS NOT RECOMMENDED                                 | -->
<!-- =================================================================================== -->
<robot name="ezgripper_stand_alone" xmlns:xacro="http://www.ros.org/wiki/xacro">
  <!--macro name="ezgripper" params="*origin"-->
  <!-- joints -->
  <!-- transmissions for Gazebo -->
  <gazebo>
    <plugin filename="libgazebo_ros_control.so" name="gazebo_ros_control">
    </plugin>
  </gazebo>

  <gazebo>
    <plugin name="joint_state_publisher" filename="libgazebo_ros_joint_state_publisher.so">
      <jointName>
        only_ezgripper_knuckle_1,
        only_ezgripper_knuckle_2,
        only_ezgripper_tip_joint_1,
        only_ezgripper_tip_joint_2,
        spring_force_calculation_joint
      </jointName>
    </plugin>
  </gazebo>

  <!-- Add the gripper -->
  <!-- links -->
  <link name="world"/>
  <link name="ezgripper_xy">
    <inertial>
      <origin xyz="0 0 0" rpy="0 0 0"/>
      <mass value="1"/>
      <inertia
        ixx="1.0" ixy="0.0" ixz="0.0"
        iyy="1.0" iyz="0.0"
        izz="1.0"/>
    </inertial>
  </link>
  <link name="ezgripper_yz">
    <inertial>
      <origin xyz="0 0 0" rpy="0 0 0"/>
      <mass value="1"/>
      <inertia
        ixx="1.0" ixy="0.0" ixz="0.0"
        iyy="1.0" iyz="0.0"
        izz="1.0"/>
    </inertial>
  </link>
  <link name="ezgripper_z_rx">
    <inertial>
      <origin xyz="0 0 0" rpy="0 0 0"/>
      <mass value="1"/>
      <inertia
        ixx="1.0" ixy="0.0" ixz="0.0"
        iyy="1.0" iyz="0.0"
        izz="1.0"/>
    </inertial>
  </link>
  <link name="ezgripper_rx_ry">
    <inertial>
      <origin xyz="0 0 0" rpy="0 0 0"/>
      <mass value="1"/>
      <inertia
        ixx="1.0" ixy="0.0" ixz="0.0"
        iyy="1.0" iyz="0.0"
        izz="1.0"/>
    </inertial>
  </link>
  <link name="ezgripper_ry_rz">
    <inertial>
      <origin xyz="0 0 0" rpy="0 0 0"/>
      <mass value="1"/>
      <inertia
        ixx="1.0" ixy="0.0" ixz="0.0"
        iyy="1.0" iyz="0.0"
        izz="1.0"/>
    </inertial>
  </link>

  <joint name="ezgripper_base_x" type="prismatic">
    <origin rpy="0 0 0" xyz="0.0 0.0 0"/>
    <parent link="world"/>
    <child link="ezgripper_xy"/>
    <axis xyz="1 0 0"/>
    <limit effort="100" velocity="10"/>
  </joint>
  <joint name="ezgripper_base_y" type="prismatic">
    <origin rpy="0 0 0" xyz="0.0 0.0 0"/>
    <parent link="ezgripper_xy"/>
    <child link="ezgripper_yz"/>
    <axis xyz="0 1 0"/>
    <limit effort="100" velocity="10"/>
  </joint>
  <joint name="ezgripper_base_z" type="prismatic">
    <origin rpy="0 0 0" xyz="0.0 0.0 1"/>
    <parent link="ezgripper_yz"/>
    <child link="ezgripper_z_rx"/>
    <axis xyz="0 0 1"/>
    <limit effort="100" velocity="10"/>
  </joint>
  <joint name="ezgripper_base_r_x" type="revolute">
    <origin rpy="0 0 0" xyz="0.0 0.0 0"/>
    <parent link="ezgripper_z_rx"/>
    <child link="ezgripper_rx_ry"/>
    <axis xyz="1 0 0"/>
    <limit effort="100" velocity="3.67"/>
  </joint>
  <joint name="ezgripper_base_r_y" type="revolute">
    <origin rpy="0 0 0" xyz="0.0 0.0 0"/>
    <parent link="ezgripper_rx_ry"/>
    <child link="ezgripper_ry_rz"/>
    <axis xyz="0 1 0"/>
    <limit effort="100" velocity="3.67"/>
  </joint>
  <joint name="ezgripper_base_r_z" type="revolute">
    <origin rpy="0 0 0" xyz="0 0 0"/>
    <parent link="ezgripper_ry_rz"/>
    <child link="only_ezgripper_palm_link"/>
    <axis xyz="0 0 1"/>
    <limit effort="100" velocity="3.67"/>
  </joint>

  <link name="only_ezgripper_palm_link">
    <visual>
      <origin rpy="0 0 0" xyz="0 0 0"/>
      <geometry>
        <mesh filename="package://ezgripper_driver/meshes/visual/SAKE_Palm_Dual.stl"/>
      </geometry>
    </visual>
    <collision>
      <origin rpy="0 0 0" xyz="0 0 0"/>
      <geometry>
        <mesh filename="package://ezgripper_driver/meshes/collision/SAKE_Palm_Dual.stl"/>
      </geometry>
    </collision>
    <inertial>
      <origin rpy="0 0 0" xyz="0 0 0"/>
      <mass value=".3"/>
      <inertia ixx="0.01" ixy="0.0" ixz="0.0" iyy="0.01" iyz="0.0" izz="0.01"/>
    </inertial>
    <gravity>0</gravity>
  </link>

  <link name="only_ezgripper_finger_1">
    <visual>
      <origin rpy="0 0 0" xyz="0 0 0"/>
      <geometry>
        <mesh filename="package://ezgripper_driver/meshes/visual/SAKE_Finger_Link1.stl"/>
      </geometry>
    </visual>
    <collision>
      <origin rpy="0 0 0" xyz="0 0 0"/>
      <geometry>
        <mesh filename="package://ezgripper_driver/meshes/collision/SAKE_Finger_Link1.stl"/>
      </geometry>
    </collision>
    <inertial>
      <origin rpy="0 0 0" xyz="-0.03121 0 -0.00256"/>
      <mass value=".025"/>
      <inertia ixx="0.01" ixy="0.0" ixz="0.0" iyy="0.01" iyz="0.0" izz="0.01"/>
    </inertial>
  </link>

  <link name="only_ezgripper_finger_2">
    <visual>
      <origin rpy="0 0 0" xyz="0 0 0"/>
      <geometry>
        <mesh filename="package://ezgripper_driver/meshes/visual/SAKE_Finger_Link1.stl"/>
      </geometry>
    </visual>
    <collision>
      <origin rpy="0 0 0" xyz="0 0 0"/>
      <geometry>
        <mesh filename="package://ezgripper_driver/meshes/collision/SAKE_Finger_Link1.stl"/>
      </geometry>
    </collision>
    <inertial>
      <origin rpy="0 0 0" xyz="-0.03121 0 -0.00256"/>
      <mass value=".025"/>
      <inertia ixx="0.01" ixy="0.0" ixz="0.0" iyy="0.01" iyz="0.0" izz="0.01"/>
    </inertial>
  </link>

  <joint name="only_ezgripper_knuckle_1" type="revolute">
    <parent link="only_ezgripper_palm_link"/>
    <child link="only_ezgripper_finger_1"/>
    <origin rpy="1.5708 0 3.14159" xyz="0.1056 0.03 0"/>
    <axis xyz="0 1 0"/>
    <limit effort="1" lower="-.27" upper="1.57075" velocity="3.67"/>
  </joint>

  <joint name="only_ezgripper_knuckle_2" type="revolute">
    <parent link="only_ezgripper_palm_link"/>
    <child link="only_ezgripper_finger_2"/>
    <origin rpy="-1.5708 0 3.14159" xyz="0.1056 -0.03 0"/>
    <axis xyz="0 1 0"/>
    <limit effort="1" lower="-.27" upper="1.57075" velocity="3.67"/>
  </joint>

  <link name="only_ezgripper_finger_tip_1">
    <visual>
      <origin rpy="0 0 0" xyz="0 0 0"/>
      <geometry>
        <mesh filename="package://ezgripper_driver/meshes/visual/SAKE_Finger_Link2.stl"/>
      </geometry>
    </visual>
    <collision>
      <origin rpy="0 0 0" xyz="0 0 0"/>
      <geometry>
        <mesh filename="package://ezgripper_driver/meshes/collision/SAKE_Finger_Link2.stl"/>
      </geometry>
    </collision>
    <inertial>
      <origin rpy="0 0 0" xyz="-0.03108 0 -0.00325"/>
      <mass value=".025"/>
      <inertia ixx="0.01" ixy="0.0" ixz="0.0" iyy="0.01" iyz="0.0" izz="0.01"/>
    </inertial>
  </link>

  <link name="only_ezgripper_finger_tip_2">
    <visual>
      <origin rpy="0 0 0" xyz="0 0 0"/>
      <geometry>
        <mesh filename="package://ezgripper_driver/meshes/visual/SAKE_Finger_Link2.stl"/>
      </geometry>
    </visual>
    <collision>
      <origin rpy="0 0 0" xyz="0 0 0"/>
      <geometry>
        <mesh filename="package://ezgripper_driver/meshes/collision/SAKE_Finger_Link2.stl"/>
      </geometry>
    </collision>
    <inertial>
      <origin rpy="0 0 0" xyz="-0.03108 0 -0.00325"/>
      <mass value=".025"/>
      <inertia ixx="0.01" ixy="0.0" ixz="0.0" iyy="0.01" iyz="0.0" izz="0.01"/>
    </inertial>
  </link>

  <joint name="only_ezgripper_tip_joint_1" type="revolute">
    <parent link="only_ezgripper_finger_1"/>
    <child link="only_ezgripper_finger_tip_1"/>
    <origin rpy="0 0.31 0" xyz="-0.0655 0 0"/>
    <axis xyz="0 1 0"/>
    <limit effort="1" lower="-1.57" upper="0.31" velocity="3.67"/>
  </joint>

  <joint name="only_ezgripper_tip_joint_2" type="revolute">
    <parent link="only_ezgripper_finger_2"/>
    <child link="only_ezgripper_finger_tip_2"/>
    <origin rpy="0 0.31 0" xyz="-0.0655 0 0"/>
    <axis xyz="0 1 0"/>
    <limit effort="1" lower="-1.57" upper="0.31" velocity="3.67"/>
  </joint>

  <link name="spring_force_calculation_link">
    <visual>
      <origin rpy="0 0 0" xyz="0 0 0"/>
      <geometry>
        <box size="0.01 0.01 0.01">
        </box>
      </geometry>
    </visual>
    <inertial>
      <origin rpy="0 0 0" xyz="0.005 0.005 0.005"/>
      <mass value=".05"/>
      <inertia ixx="0.01" ixy="0.0" ixz="0.0" iyy="0.01" iyz="0.0" izz="0.01"/>
    </inertial>
  </link>

  <joint name="spring_force_calculation_joint" type="revolute">
    <parent link="only_ezgripper_palm_link"/>
    <child link="spring_force_calculation_link"/>
    <origin rpy="0 0 0" xyz="0 0 0.063"/>
    <axis xyz="0 1 0"/>
    <limit effort="1" lower="-.27" upper="1.57075" velocity="3.67"/>
  </joint>

  <transmission name="only_ezgripper_trans_1">
    <type>transmission_interface/SimpleTransmission</type>
    <joint name="only_ezgripper_knuckle_1">
      <hardwareInterface>EffortJointInterface</hardwareInterface>
    </joint>
    <actuator name="only_ezgripper_motor1">
      <mechanicalReduction>1</mechanicalReduction>
      <hardwareInterface>EffortJointInterface</hardwareInterface>
    </actuator>
  </transmission>

  <transmission name="only_ezgripper_trans_2">
    <type>transmission_interface/SimpleTransmission</type>
    <joint name="only_ezgripper_knuckle_2">
      <hardwareInterface>EffortJointInterface</hardwareInterface>
    </joint>
    <actuator name="only_ezgripper_motor2">
      <mechanicalReduction>1</mechanicalReduction>
      <hardwareInterface>EffortJointInterface</hardwareInterface>
    </actuator>
  </transmission>

  <transmission name="only_ezgripper_trans_3">
    <type>transmission_interface/SimpleTransmission</type>
    <joint name="only_ezgripper_tip_joint_1">
      <hardwareInterface>EffortJointInterface</hardwareInterface>
    </joint>
    <actuator name="only_ezgripper_motor3">
      <mechanicalReduction>1</mechanicalReduction>
      <hardwareInterface>EffortJointInterface</hardwareInterface>
    </actuator>
  </transmission>

  <transmission name="only_ezgripper_trans_4">
    <type>transmission_interface/SimpleTransmission</type>
    <joint name="only_ezgripper_tip_joint_2">
      <hardwareInterface>EffortJointInterface</hardwareInterface>
    </joint>
    <actuator name="only_ezgripper_motor4">
      <mechanicalReduction>1</mechanicalReduction>
      <hardwareInterface>EffortJointInterface</hardwareInterface>
    </actuator>
  </transmission>

  <transmission name="only_ezgripper_trans_5">
    <type>transmission_interface/SimpleTransmission</type>
    <joint name="spring_force_calculation_joint">
      <hardwareInterface>EffortJointInterface</hardwareInterface>
    </joint>
    <actuator name="only_ezgripper_motor5">
      <mechanicalReduction>1</mechanicalReduction>
      <hardwareInterface>EffortJointInterface</hardwareInterface>
    </actuator>
  </transmission>

  <transmission name="only_ezgripper_trans_x">
    <type>transmission_interface/SimpleTransmission</type>
    <joint name="ezgripper_base_x">
      <hardwareInterface>PositionJointInterface</hardwareInterface>
    </joint>
    <actuator name="only_ezgripper_motor6">
      <mechanicalReduction>1</mechanicalReduction>
      <hardwareInterface>PositionJointInterface</hardwareInterface>
    </actuator>
  </transmission>

  <transmission name="only_ezgripper_trans_y">
    <type>transmission_interface/SimpleTransmission</type>
    <joint name="ezgripper_base_y">
      <hardwareInterface>PositionJointInterface</hardwareInterface>
    </joint>
    <actuator name="only_ezgripper_motor7">
      <mechanicalReduction>1</mechanicalReduction>
      <hardwareInterface>PositionJointInterface</hardwareInterface>
    </actuator>
  </transmission>

  <transmission name="only_ezgripper_trans_z">
    <type>transmission_interface/SimpleTransmission</type>
    <joint name="ezgripper_base_z">
      <hardwareInterface>PositionJointInterface</hardwareInterface>
    </joint>
    <actuator name="only_ezgripper_motor8">
      <mechanicalReduction>1</mechanicalReduction>
      <hardwareInterface>PositionJointInterface</hardwareInterface>
    </actuator>
  </transmission>

  <transmission name="only_ezgripper_trans_r_x">
    <type>transmission_interface/SimpleTransmission</type>
    <joint name="ezgripper_base_r_x">
      <hardwareInterface>PositionJointInterface</hardwareInterface>
    </joint>
    <actuator name="only_ezgripper_motor9">
      <mechanicalReduction>1</mechanicalReduction>
      <hardwareInterface>PositionJointInterface</hardwareInterface>
    </actuator>
  </transmission>

  <transmission name="only_ezgripper_trans_r_y">
    <type>transmission_interface/SimpleTransmission</type>
    <joint name="ezgripper_base_r_y">
      <hardwareInterface>PositionJointInterface</hardwareInterface>
    </joint>
    <actuator name="only_ezgripper_motor10">
      <mechanicalReduction>1</mechanicalReduction>
      <hardwareInterface>PositionJointInterface</hardwareInterface>
    </actuator>
  </transmission>

  <transmission name="only_ezgripper_trans_r_z">
    <type>transmission_interface/SimpleTransmission</type>
    <joint name="ezgripper_base_r_z">
      <hardwareInterface>PositionJointInterface</hardwareInterface>
    </joint>
    <actuator name="only_ezgripper_motor11">
      <mechanicalReduction>1</mechanicalReduction>
      <hardwareInterface>PositionJointInterface</hardwareInterface>
    </actuator>
  </transmission>
</robot>

