<?xml version="1.0" ?>
<!-- =================================================================================== -->
<!-- |    This document was autogenerated by xacro from ezgripper_quad_standalone.urdf.xacro | -->
<!-- |    EDITING THIS FILE BY HAND IS NOT RECOMMENDED                                 | -->
<!-- =================================================================================== -->
<robot name="ezgripper_stand_alone" xmlns:xacro="http://www.ros.org/wiki/xacro">
  <!-- joints -->
  <!-- transmissions for Gazebo -->
  <gazebo>
    <plugin filename="libgazebo_ros_control.so" name="gazebo_ros_control">
       
   </plugin>
  </gazebo>
  <!-- Add the gripper -->
  <!-- links -->
  <link name="only_ezgripper_palm_link">
    <visual>
      <origin rpy="0 0 0" xyz="0 0 0"/>
      <geometry>
        <mesh filename="package://ezgripper_driver/meshes/visual/SAKE_Palm_Quad.stl"/>
      </geometry>
    </visual>
    <collision>
      <origin rpy="0 0 0" xyz="0 0 0"/>
      <geometry>
        <mesh filename="package://ezgripper_driver/meshes/collision/SAKE_Palm_Quad.stl"/>
      </geometry>
    </collision>
    <inertial>
      <mass value=".3"/>
      <inertia ixx="0.01" ixy="0.0" ixz="0.0" iyy="0.01" iyz="0.0" izz="0.01"/>
    </inertial>
  </link>
  <joint name="only_ezgripper_connect" type="fixed">
    <origin rpy="-1.57 0 0" xyz="0.049 0.0 0.2"/>
    <parent link="base_link"/>
    <child link="only_ezgripper_palm_link"/>
    <axis xyz="0 0 0"/>
    <limit effort="0" lower="-1.57075" upper="0.25" velocity="3.67"/>
  </joint>
  <link name="only_ezgripper_finger_1">
    <visual>
      <origin rpy="0 0 0" xyz="0 0 0"/>
      <geometry>
        <mesh filename="package://ezgripper_driver/meshes/visual/SAKE_Finger.stl"/>
      </geometry>
    </visual>
    <collision>
      <origin rpy="0 0 0" xyz="0 0 0"/>
      <geometry>
        <mesh filename="package://ezgripper_driver/meshes/collision/SAKE_Finger.stl"/>
      </geometry>
    </collision>
    <inertial>
      <mass value=".025"/>
      <inertia ixx="0.01" ixy="0.0" ixz="0.0" iyy=".01" iyz="0.0" izz="0.01"/>
    </inertial>
  </link>
  <link name="only_ezgripper_finger_2">
    <visual>
      <origin rpy="0 0 0" xyz="0 0 0"/>
      <geometry>
        <mesh filename="package://ezgripper_driver/meshes/visual/SAKE_Finger.stl"/>
      </geometry>
    </visual>
    <collision>
      <origin rpy="0 0 0" xyz="0 0 0"/>
      <geometry>
        <mesh filename="package://ezgripper_driver/meshes/collision/SAKE_Finger.stl"/>
      </geometry>
    </collision>
    <inertial>
      <mass value=".025"/>
      <inertia ixx="0.01" ixy="0.0" ixz="0.0" iyy=".01" iyz="0.0" izz="0.01"/>
    </inertial>
  </link>
  <link name="only_ezgripper_finger_3">
    <visual>
      <origin rpy="0 0 0" xyz="0 0 0"/>
      <geometry>
        <mesh filename="package://ezgripper_driver/meshes/visual/SAKE_Finger.stl"/>
      </geometry>
    </visual>
    <collision>
      <origin rpy="0 0 0" xyz="0 0 0"/>
      <geometry>
        <mesh filename="package://ezgripper_driver/meshes/collision/SAKE_Finger.stl"/>
      </geometry>
    </collision>
    <inertial>
      <mass value=".025"/>
      <inertia ixx="0.01" ixy="0.0" ixz="0.0" iyy=".01" iyz="0.0" izz="0.01"/>
    </inertial>
  </link>
  <link name="only_ezgripper_finger_4">
    <visual>
      <origin rpy="0 0 0" xyz="0 0 0"/>
      <geometry>
        <mesh filename="package://ezgripper_driver/meshes/visual/SAKE_Finger.stl"/>
      </geometry>
    </visual>
    <collision>
      <origin rpy="0 0 0" xyz="0 0 0"/>
      <geometry>
        <mesh filename="package://ezgripper_driver/meshes/collision/SAKE_Finger.stl"/>
      </geometry>
    </collision>
    <inertial>
      <mass value=".025"/>
      <inertia ixx="0.01" ixy="0.0" ixz="0.0" iyy=".01" iyz="0.0" izz="0.01"/>
    </inertial>
  </link>
  <joint name="only_ezgripper_knuckle_1" type="revolute">
    <parent link="only_ezgripper_palm_link"/>
    <child link="only_ezgripper_finger_1"/>
    <origin rpy="1.5708 0 3.14159" xyz="0.1056 0.03 0.03"/>
    <axis xyz="0 1 0"/>
    <limit effort="1" lower="-.27" upper="1.57075" velocity="3.67"/>
    <physics>
	  <ode>
	    <limit>
	      <cfm>30.0</cfm>
	      <erp>10.0</erp>
	    </limit>
	  </ode>
	</physics>
  </joint>
  <joint name="only_ezgripper_knuckle_2" type="revolute">
    <parent link="only_ezgripper_palm_link"/>
    <child link="only_ezgripper_finger_2"/>
    <origin rpy="-1.5708 0 3.14159" xyz="0.1056 -0.03 0.03"/>
    <axis xyz="0 1 0"/>
    <limit effort="1" lower="-.27" upper="1.57075" velocity="3.67"/>
    <mimic joint="only_ezgripper_knuckle_1"/>
    <physics>
	  <ode>
	    <limit>
	      <cfm>30.0</cfm>
	      <erp>10.0</erp>
	    </limit>
	  </ode>
	</physics>
  </joint>
  <joint name="only_ezgripper_knuckle_3" type="revolute">
    <parent link="only_ezgripper_palm_link"/>
    <child link="only_ezgripper_finger_3"/>
    <origin rpy="1.5708 0 3.14159" xyz="0.1056 0.03 -0.03"/>
    <axis xyz="0 1 0"/>
    <limit effort="1" lower="-.27" upper="1.57075" velocity="3.67"/>
    <mimic joint="only_ezgripper_knuckle_1"/>
    <physics>
	  <ode>
	    <limit>
	      <cfm>30.0</cfm>
	      <erp>10.0</erp>
	    </limit>
	  </ode>
	</physics>
  </joint>
  <joint name="only_ezgripper_knuckle_4" type="revolute">
    <parent link="only_ezgripper_palm_link"/>
    <child link="only_ezgripper_finger_4"/>
    <origin rpy="-1.5708 0 3.14159" xyz="0.1056 -0.03 -0.03"/>
    <axis xyz="0 1 0"/>
    <limit effort="1" lower="-.27" upper="1.57075" velocity="3.67"/>
    <mimic joint="only_ezgripper_knuckle_1"/>
    <physics>
	  <ode>
	    <limit>
	      <cfm>30.0</cfm>
	      <erp>10.0</erp>
	    </limit>
	  </ode>
	</physics>
  </joint>
  <transmission name="only_ezgripper_trans_1">
    <type>transmission_interface/SimpleTransmission</type>
    <joint name="only_ezgripper_knuckle_1">
      <hardwareInterface>PositionJointInterface</hardwareInterface>
    </joint>
    <actuator name="only_ezgripper_motor1">
      <mechanicalReduction>1</mechanicalReduction>
      <hardwareInterface>PositionJointInterface</hardwareInterface>
    </actuator>
  </transmission>
  <transmission name="only_ezgripper_trans_2">
    <type>transmission_interface/SimpleTransmission</type>
    <joint name="only_ezgripper_knuckle_2">
      <hardwareInterface>PositionJointInterface</hardwareInterface>
    </joint>
    <actuator name="only_ezgripper_motor2">
      <mechanicalReduction>1</mechanicalReduction>
      <hardwareInterface>PositionJointInterface</hardwareInterface>
    </actuator>
  </transmission>
  <transmission name="only_ezgripper_trans_3">
    <type>transmission_interface/SimpleTransmission</type>
    <joint name="only_ezgripper_knuckle_3">
      <hardwareInterface>PositionJointInterface</hardwareInterface>
    </joint>
    <actuator name="only_ezgripper_motor3">
      <mechanicalReduction>1</mechanicalReduction>
      <hardwareInterface>PositionJointInterface</hardwareInterface>
    </actuator>
  </transmission>
  <transmission name="only_ezgripper_trans_4">
    <type>transmission_interface/SimpleTransmission</type>
    <joint name="only_ezgripper_knuckle_4">
      <hardwareInterface>PositionJointInterface</hardwareInterface>
    </joint>
    <actuator name="only_ezgripper_motor4">
      <mechanicalReduction>1</mechanicalReduction>
      <hardwareInterface>PositionJointInterface</hardwareInterface>
    </actuator>
  </transmission>
  <gazebo>
    <plugin filename="libgazebo_ros_joint_state_publisher.so" name="joint_state_publisher">
      <jointName>only_ezgripper_knuckle_1,only_ezgripper_knuckle_2,only_ezgripper_knuckle_3,only_ezgripper_knuckle_4  </jointName>
    </plugin>
  </gazebo>
  <link name="world"/>
  <joint name="fixed" type="fixed">
    <parent link="world"/>
    <child link="base_link"/>
  </joint>
  <link name="base_link">
    <visual>
      <geometry>
        <cylinder length="0.42" radius="0.02"/>
      </geometry>
      <origin rpy="0 0 0" xyz="0 0 0.21"/>
      <material name="red"/>
    </visual>
  </link>
</robot>

